<mujoco model="a1">
  <compiler angle="radian" meshdir="assets" texturedir="assets" autolimits="true"/>

  <option cone="elliptic" impratio="100"/>

  <default>
    <default class="a1">
      <geom friction="0.6" margin="0.001"/>
      <joint axis="0 1 0" damping="2" armature="0.01" frictionloss="0.2"/>
      <position kp="20" kv="0.5" forcerange="-33.5 33.5"/>
      <default class="abduction">
        <joint axis="1 0 0" damping="1" range="-0.802851 0.802851"/>
        <position ctrlrange="-0.802851 0.802851"/>
      </default>
      <default class="hip">
        <joint range="-1.0472 4.18879"/>
        <position ctrlrange="-1.0472 4.18879"/>
      </default>
      <default class="knee">
        <joint range="-2.69653 -0.916298"/>
        <position ctrlrange="-2.69653 -0.916298"/>
      </default>
      <default class="visual">
        <geom type="mesh" contype="0" conaffinity="0" group="2" material="dark"/>
      </default>
      <default class="collision">
        <geom group="3" type="capsule"/>
        <default class="hip_left">
          <geom size="0.04 0.04" quat="1 1 0 0" type="cylinder" pos="0 0.055 0"/>
        </default>
        <default class="hip_right">
          <geom size="0.04 0.04" quat="1 1 0 0" type="cylinder" pos="0 -0.055 0"/>
        </default>
        <default class="thigh1">
          <geom size="0.015" fromto="-0.02 0 0 -0.02 0 -0.16"/>
        </default>
        <default class="thigh2">
          <geom size="0.015" fromto="0 0 0 -0.02 0 -0.1"/>
        </default>
        <default class="thigh3">
          <geom size="0.015" fromto="-0.02 0 -0.16 0 0 -0.2"/>
        </default>
        <default class="calf1">
          <geom size="0.01" fromto="0 0 0 0.02 0 -0.13"/>
        </default>
        <default class="calf2">
          <geom size="0.01" fromto="0.02 0 -0.13 0 0 -0.2"/>
        </default>
        <default class="foot">
          <geom type="sphere" size="0.02" pos="0 0 -0.2" priority="1" solimp="0.015 1 0.02" condim="6"
            friction="0.8 0.02 0.01"/>
        </default>
      </default>
    </default>
  </default>

  <asset>
    <material name="dark" specular="0" shininess="0.25" rgba="0.2 0.2 0.2 1"/>
    <texture type="2d" name="trunk_A1" file="trunk_A1.png"/>
    <material name="carbonfibre" texture="trunk_A1" specular="0" shininess="0.25"/>

    <mesh class="a1" file="calf.obj"/>
    <mesh class="a1" file="hip.obj"/>
    <mesh class="a1" file="thigh.obj"/>
    <mesh class="a1" file="thigh_mirror.obj"/>
    <mesh class="a1" file="trunk.obj"/>
  </asset>

  <worldbody>
    <light name="spotlight" mode="targetbodycom" target="trunk" pos="0 -1 2"/>
    <body name="trunk" pos="0 0 0.43" childclass="a1">
      <freejoint/>
      <inertial mass="4.713" pos="0 0.0041 -0.0005"
        fullinertia="0.0158533 0.0377999 0.0456542 -3.66e-05 -6.11e-05 -2.75e-05"/>
      <geom class="visual" mesh="trunk" material="carbonfibre"/>
      <geom class="collision" size="0.125 0.04 0.057" type="box"/>
      <geom class="collision" quat="1 0 1 0" pos="0 -0.04 0" size="0.058 0.125" type="cylinder"/>
      <geom class="collision" quat="1 0 1 0" pos="0 +0.04 0" size="0.058 0.125" type="cylinder"/>
      <geom class="collision" pos="0.25 0 0" size="0.005 0.06 0.05" type="box"/>
      <geom class="collision" pos="0.25 0.06 -0.01" size="0.009 0.035"/>
      <geom class="collision" pos="0.25 -0.06 -0.01" size="0.009 0.035"/>
      <geom class="collision" pos="0.25 0 -0.05" size="0.005 0.06" quat="1 1 0 0"/>
      <geom class="collision" pos="0.255 0 0.0355" size="0.021 0.052" quat="1 1 0 0"/>
      
      <!-- Lidar body on top of trunk -->
      <body name="lidar_body" pos="0.15 0 0.12" euler="0 1.5708 0">
        <site name="lidar_origin" pos="0 0 0" size="0.02" type="sphere" rgba="1 0 0 0.5" />
        <!-- 40 evenly spaced lidar beams covering full 360 degrees (9 degrees apart) -->
        <site name="lidar_beam_0" pos="0 0 0" euler="0.000000 0 0" size="0.01" />
        <site name="lidar_beam_1" pos="0 0 0" euler="0.157080 0 0" size="0.01" />
        <site name="lidar_beam_2" pos="0 0 0" euler="0.314159 0 0" size="0.01" />
        <site name="lidar_beam_3" pos="0 0 0" euler="0.471239 0 0" size="0.01" />
        <site name="lidar_beam_4" pos="0 0 0" euler="0.628319 0 0" size="0.01" />
        <site name="lidar_beam_5" pos="0 0 0" euler="0.785398 0 0" size="0.01" />
        <site name="lidar_beam_6" pos="0 0 0" euler="0.942478 0 0" size="0.01" />
        <site name="lidar_beam_7" pos="0 0 0" euler="1.099557 0 0" size="0.01" />
        <site name="lidar_beam_8" pos="0 0 0" euler="1.256637 0 0" size="0.01" />
        <site name="lidar_beam_9" pos="0 0 0" euler="1.413717 0 0" size="0.01" />
        <site name="lidar_beam_10" pos="0 0 0" euler="1.570796 0 0" size="0.01" />
        <site name="lidar_beam_11" pos="0 0 0" euler="1.727876 0 0" size="0.01" />
        <site name="lidar_beam_12" pos="0 0 0" euler="1.884956 0 0" size="0.01" />
        <site name="lidar_beam_13" pos="0 0 0" euler="2.042035 0 0" size="0.01" />
        <site name="lidar_beam_14" pos="0 0 0" euler="2.199115 0 0" size="0.01" />
        <site name="lidar_beam_15" pos="0 0 0" euler="2.356194 0 0" size="0.01" />
        <site name="lidar_beam_16" pos="0 0 0" euler="2.513274 0 0" size="0.01" />
        <site name="lidar_beam_17" pos="0 0 0" euler="2.670354 0 0" size="0.01" />
        <site name="lidar_beam_18" pos="0 0 0" euler="2.827433 0 0" size="0.01" />
        <site name="lidar_beam_19" pos="0 0 0" euler="2.984513 0 0" size="0.01" />
        <site name="lidar_beam_20" pos="0 0 0" euler="3.141593 0 0" size="0.01" />
        <site name="lidar_beam_21" pos="0 0 0" euler="3.298672 0 0" size="0.01" />
        <site name="lidar_beam_22" pos="0 0 0" euler="3.455752 0 0" size="0.01" />
        <site name="lidar_beam_23" pos="0 0 0" euler="3.612832 0 0" size="0.01" />
        <site name="lidar_beam_24" pos="0 0 0" euler="3.769911 0 0" size="0.01" />
        <site name="lidar_beam_25" pos="0 0 0" euler="3.926991 0 0" size="0.01" />
        <site name="lidar_beam_26" pos="0 0 0" euler="4.084070 0 0" size="0.01" />
        <site name="lidar_beam_27" pos="0 0 0" euler="4.241150 0 0" size="0.01" />
        <site name="lidar_beam_28" pos="0 0 0" euler="4.398230 0 0" size="0.01" />
        <site name="lidar_beam_29" pos="0 0 0" euler="4.555309 0 0" size="0.01" />
        <site name="lidar_beam_30" pos="0 0 0" euler="4.712389 0 0" size="0.01" />
        <site name="lidar_beam_31" pos="0 0 0" euler="4.869469 0 0" size="0.01" />
        <site name="lidar_beam_32" pos="0 0 0" euler="5.026548 0 0" size="0.01" />
        <site name="lidar_beam_33" pos="0 0 0" euler="5.183628 0 0" size="0.01" />
        <site name="lidar_beam_34" pos="0 0 0" euler="5.340708 0 0" size="0.01" />
        <site name="lidar_beam_35" pos="0 0 0" euler="5.497787 0 0" size="0.01" />
        <site name="lidar_beam_36" pos="0 0 0" euler="5.654867 0 0" size="0.01" />
        <site name="lidar_beam_37" pos="0 0 0" euler="5.811946 0 0" size="0.01" />
        <site name="lidar_beam_38" pos="0 0 0" euler="5.969026 0 0" size="0.01" />
        <site name="lidar_beam_39" pos="0 0 0" euler="6.126106 0 0" size="0.01" />
      </body>
      
      <body name="FR_hip" pos="0.183 -0.047 0">
        <inertial mass="0.696" pos="-0.003311 -0.000635 3.1e-05" quat="0.507528 0.506268 0.491507 0.494499"
          diaginertia="0.000807752 0.00055293 0.000468983"/>
        <joint class="abduction" name="FR_hip_joint"/>
        <geom class="visual" mesh="hip" quat="0 1 0 0"/>
        <geom class="hip_right"/>
        <body name="FR_thigh" pos="0 -0.08505 0">
          <inertial mass="1.013" pos="-0.003237 0.022327 -0.027326" quat="0.999125 -0.00256393 -0.0409531 -0.00806091"
            diaginertia="0.00555739 0.00513936 0.00133944"/>
          <joint class="hip" name="FR_thigh_joint"/>
          <geom class="visual" mesh="thigh_mirror"/>
          <geom class="thigh1"/>
          <geom class="thigh2"/>
          <geom class="thigh3"/>
          <body name="FR_calf" pos="0 0 -0.2">
            <inertial mass="0.226" pos="0.00472659 0 -0.131975" quat="0.706886 0.017653 0.017653 0.706886"
              diaginertia="0.00340344 0.00339393 3.54834e-05"/>
            <joint class="knee" name="FR_calf_joint"/>
            <geom class="visual" mesh="calf"/>
            <geom class="calf1"/>
            <geom class="calf2"/>
            <geom class="foot"/>
          </body>
        </body>
      </body>
      <body name="FL_hip" pos="0.183 0.047 0">
        <inertial mass="0.696" pos="-0.003311 0.000635 3.1e-05" quat="0.494499 0.491507 0.506268 0.507528"
          diaginertia="0.000807752 0.00055293 0.000468983"/>
        <joint class="abduction" name="FL_hip_joint"/>
        <geom class="visual" mesh="hip"/>
        <geom class="hip_left"/>
        <geom class="collision" size="0.04 0.04" pos="0 0.055 0" quat="1 1 0 0" type="cylinder"/>
        <body name="FL_thigh" pos="0 0.08505 0">
          <inertial mass="1.013" pos="-0.003237 -0.022327 -0.027326" quat="0.999125 0.00256393 -0.0409531 0.00806091"
            diaginertia="0.00555739 0.00513936 0.00133944"/>
          <joint class="hip" name="FL_thigh_joint"/>
          <geom class="visual" mesh="thigh"/>
          <geom class="thigh1"/>
          <geom class="thigh2"/>
          <geom class="thigh3"/>
          <body name="FL_calf" pos="0 0 -0.2">
            <inertial mass="0.226" pos="0.00472659 0 -0.131975" quat="0.706886 0.017653 0.017653 0.706886"
              diaginertia="0.00340344 0.00339393 3.54834e-05"/>
            <joint class="knee" name="FL_calf_joint"/>
            <geom class="visual" mesh="calf"/>
            <geom class="calf1"/>
            <geom class="calf2"/>
            <geom class="foot"/>
          </body>
        </body>
      </body>
      <body name="RR_hip" pos="-0.183 -0.047 0">
        <inertial mass="0.696" pos="0.003311 -0.000635 3.1e-05" quat="0.491507 0.494499 0.507528 0.506268"
          diaginertia="0.000807752 0.00055293 0.000468983"/>
        <joint class="abduction" name="RR_hip_joint"/>
        <geom class="visual" quat="0 0 0 -1" mesh="hip"/>
        <geom class="hip_right"/>
        <body name="RR_thigh" pos="0 -0.08505 0">
          <inertial mass="1.013" pos="-0.003237 0.022327 -0.027326" quat="0.999125 -0.00256393 -0.0409531 -0.00806091"
            diaginertia="0.00555739 0.00513936 0.00133944"/>
          <joint class="hip" name="RR_thigh_joint"/>
          <geom class="visual" mesh="thigh_mirror"/>
          <geom class="thigh1"/>
          <geom class="thigh2"/>
          <geom class="thigh3"/>
          <body name="RR_calf" pos="0 0 -0.2">
            <inertial mass="0.226" pos="0.00472659 0 -0.131975" quat="0.706886 0.017653 0.017653 0.706886"
              diaginertia="0.00340344 0.00339393 3.54834e-05"/>
            <joint class="knee" name="RR_calf_joint"/>
            <geom class="visual" mesh="calf"/>
            <geom class="calf1"/>
            <geom class="calf2"/>
            <geom class="foot"/>
          </body>
        </body>
      </body>
      <body name="RL_hip" pos="-0.183 0.047 0">
        <inertial mass="0.696" pos="0.003311 0.000635 3.1e-05" quat="0.506268 0.507528 0.494499 0.491507"
          diaginertia="0.000807752 0.00055293 0.000468983"/>
        <joint class="abduction" name="RL_hip_joint"/>
        <geom class="visual" quat="0 0 1 0" mesh="hip"/>
        <geom class="hip_left"/>
        <body name="RL_thigh" pos="0 0.08505 0">
          <inertial mass="1.013" pos="-0.003237 -0.022327 -0.027326" quat="0.999125 0.00256393 -0.0409531 0.00806091"
            diaginertia="0.00555739 0.00513936 0.00133944"/>
          <joint class="hip" name="RL_thigh_joint"/>
          <geom class="visual" mesh="thigh"/>
          <geom class="thigh1"/>
          <geom class="thigh2"/>
          <geom class="thigh3"/>
          <body name="RL_calf" pos="0 0 -0.2">
            <inertial mass="0.226" pos="0.00472659 0 -0.131975" quat="0.706886 0.017653 0.017653 0.706886"
              diaginertia="0.00340344 0.00339393 3.54834e-05"/>
            <joint class="knee" name="RL_calf_joint"/>
            <geom class="visual" mesh="calf"/>
            <geom class="calf1"/>
            <geom class="calf2"/>
            <geom class="foot"/>
          </body>
        </body>
      </body>
    </body>
  </worldbody>

  <actuator>
    <position class="abduction" name="FR_hip" joint="FR_hip_joint"/>
    <position class="hip" name="FR_thigh" joint="FR_thigh_joint"/>
    <position class="knee" name="FR_calf" joint="FR_calf_joint"/>
    <position class="abduction" name="FL_hip" joint="FL_hip_joint"/>
    <position class="hip" name="FL_thigh" joint="FL_thigh_joint"/>
    <position class="knee" name="FL_calf" joint="FL_calf_joint"/>
    <position class="abduction" name="RR_hip" joint="RR_hip_joint"/>
    <position class="hip" name="RR_thigh" joint="RR_thigh_joint"/>
    <position class="knee" name="RR_calf" joint="RR_calf_joint"/>
    <position class="abduction" name="RL_hip" joint="RL_hip_joint"/>
    <position class="hip" name="RL_thigh" joint="RL_thigh_joint"/>
    <position class="knee" name="RL_calf" joint="RL_calf_joint"/>
  </actuator>

  <sensor>
    <!-- 40 evenly spaced lidar rangefinders covering full 360 degrees -->
    <rangefinder name="lidar_0" site="lidar_beam_0" cutoff="3.0" />
    <rangefinder name="lidar_1" site="lidar_beam_1" cutoff="3.0" />
    <rangefinder name="lidar_2" site="lidar_beam_2" cutoff="3.0" />
    <rangefinder name="lidar_3" site="lidar_beam_3" cutoff="3.0" />
    <rangefinder name="lidar_4" site="lidar_beam_4" cutoff="3.0" />
    <rangefinder name="lidar_5" site="lidar_beam_5" cutoff="3.0" />
    <rangefinder name="lidar_6" site="lidar_beam_6" cutoff="3.0" />
    <rangefinder name="lidar_7" site="lidar_beam_7" cutoff="3.0" />
    <rangefinder name="lidar_8" site="lidar_beam_8" cutoff="3.0" />
    <rangefinder name="lidar_9" site="lidar_beam_9" cutoff="3.0" />
    <rangefinder name="lidar_10" site="lidar_beam_10" cutoff="3.0" />
    <rangefinder name="lidar_11" site="lidar_beam_11" cutoff="3.0" />
    <rangefinder name="lidar_12" site="lidar_beam_12" cutoff="3.0" />
    <rangefinder name="lidar_13" site="lidar_beam_13" cutoff="3.0" />
    <rangefinder name="lidar_14" site="lidar_beam_14" cutoff="3.0" />
    <rangefinder name="lidar_15" site="lidar_beam_15" cutoff="3.0" />
    <rangefinder name="lidar_16" site="lidar_beam_16" cutoff="3.0" />
    <rangefinder name="lidar_17" site="lidar_beam_17" cutoff="3.0" />
    <rangefinder name="lidar_18" site="lidar_beam_18" cutoff="3.0" />
    <rangefinder name="lidar_19" site="lidar_beam_19" cutoff="3.0" />
    <rangefinder name="lidar_20" site="lidar_beam_20" cutoff="3.0" />
    <rangefinder name="lidar_21" site="lidar_beam_21" cutoff="3.0" />
    <rangefinder name="lidar_22" site="lidar_beam_22" cutoff="3.0" />
    <rangefinder name="lidar_23" site="lidar_beam_23" cutoff="3.0" />
    <rangefinder name="lidar_24" site="lidar_beam_24" cutoff="3.0" />
    <rangefinder name="lidar_25" site="lidar_beam_25" cutoff="3.0" />
    <rangefinder name="lidar_26" site="lidar_beam_26" cutoff="3.0" />
    <rangefinder name="lidar_27" site="lidar_beam_27" cutoff="3.0" />
    <rangefinder name="lidar_28" site="lidar_beam_28" cutoff="3.0" />
    <rangefinder name="lidar_29" site="lidar_beam_29" cutoff="3.0" />
    <rangefinder name="lidar_30" site="lidar_beam_30" cutoff="3.0" />
    <rangefinder name="lidar_31" site="lidar_beam_31" cutoff="3.0" />
    <rangefinder name="lidar_32" site="lidar_beam_32" cutoff="3.0" />
    <rangefinder name="lidar_33" site="lidar_beam_33" cutoff="3.0" />
    <rangefinder name="lidar_34" site="lidar_beam_34" cutoff="3.0" />
    <rangefinder name="lidar_35" site="lidar_beam_35" cutoff="3.0" />
    <rangefinder name="lidar_36" site="lidar_beam_36" cutoff="3.0" />
    <rangefinder name="lidar_37" site="lidar_beam_37" cutoff="3.0" />
    <rangefinder name="lidar_38" site="lidar_beam_38" cutoff="3.0" />
    <rangefinder name="lidar_39" site="lidar_beam_39" cutoff="3.0" />
  </sensor>

  <keyframe>
    <key name="home" qpos="0 0 0.27 1 0 0 0 0 0.9 -1.8 0 0.9 -1.8 0 0.9 -1.8 0 0.9 -1.8"
      ctrl="0 0.9 -1.8 0 0.9 -1.8 0 0.9 -1.8 0 0.9 -1.8"/>
  </keyframe>
</mujoco>
